Workbook

Sheet 📋 Materials Checklist
A1: 🍄 KABUTECH HIYAS — COMPLETE MATERIALS & PROCUREMENT CHECKLIST
A2: Precision Mushroom Grow House Automation | Target Budget: ₱15,000 PHP | 68 Components | High-Quality Digital Sensors
A3: 💡 INSTRUCTIONS: Update 'Status' dropdown (To Buy / Ordered / Received / In Stock) as you purchase items. Enter your 'Actual Spent (₱)' to track budget in real-time.
A4: Status | B4: Code | C4: Component Name | D4: Category | E4: Technical Specifications & Rationale | F4: Qty | G4: Unit | H4: Min Est (₱) | I4: Max Est (₱) | J4: Min Total (₱) | K4: Max Total (₱) | L4: Actual Spent (₱) | M4: Recommended Vendor / Store | N4: Search Keywords / Model | O4: Procurement & Assembly Notes
A5: 🔬 CATEGORY A: SENSORS & PROBE ELECTRONICS (QUALITY-GRADE)
A6: To Buy | B6: A1 | C6: SHT31-D Temperature & Humidity Module | D6: Sensors & Probe Electronics | E6: ±2% RH, ±0.3°C accuracy. Digital I2C bus. Factory calibrated. Superior to DHT11. | F6: 1 | G6: pc | H6: 120 | I6: 180 | J6: =F6*H6 | K6: =F6*I6 | M6: Shopee / Lazada / Makerlab PH | N6: SHT31-D sensor module I2C | O6: Essential for high-humidity mushroom chamber.
A7: To Buy | B7: A2 | C7: BH1750 Digital Light Sensor (GY-302) | D7: Sensors & Probe Electronics | E7: 1–65535 lux, 16-bit resolution, direct lux output, I2C. Replaces unreliable LDR. | F7: 1 | G7: pc | H7: 80 | I7: 150 | J7: =F7*H7 | K7: =F7*I7 | M7: Shopee / Lazada / Circuit Rocks | N7: BH1750 GY-302 light sensor module | O7: Mount facing grow bags to track pinhead lighting.
A8: To Buy | B8: A3 | C8: SCD41 True NDIR CO₂ Sensor Module | D8: Sensors & Probe Electronics | E8: Photoacoustic NDIR, 400–5000 ppm, ±(40 ppm + 5%), I2C. True CO₂ measurement. | F8: 1 | G8: pc | H8: 1800 | I8: 2500 | J8: =F8*H8 | K8: =F8*I8 | M8: Shopee PH / AliExpress | N8: Sensirion SCD41 CO2 sensor module | O8: Most critical sensor for thesis credibility. Not MQ-135.
A9: To Buy | B9: A4 | C9: Capacitive Water Level Sensor (XKC-Y25-T12V) | D9: Sensors & Probe Electronics | E9: Non-contact liquid level, penetrates 20mm plastic wall, 5-24V DC, digital out. | F9: 1 | G9: pc | H9: 250 | I9: 400 | J9: =F9*H9 | K9: =F9*I9 | M9: Shopee / Lazada / Makerlab PH | N9: XKC-Y25-T12V non contact water level | O9: Outside reservoir mounting. No corrosion or electrolysis.
A10: To Buy | B10: A5 | C10: YF-S201 Water Flow Sensor (Hall Effect) | D10: Sensors & Probe Electronics | E10: 1–30 L/min range, working pressure <1.75MPa, pulse output, food-grade nylon. | F10: 1 | G10: pc | H10: 150 | I10: 220 | J10: =F10*H10 | K10: =F10*I10 | M10: Shopee / Lazada | N10: YF-S201 water flow sensor 1/2 inch | O10: Monitors mist delivery & alerts if reservoir runs dry.
A11: To Buy | B11: A6 | C11: 0.96" SSD1306 OLED Display (I2C) | D11: Sensors & Probe Electronics | E11: 128×64 resolution, monochrome white/blue, I2C address 0x3C, 3.3V/5V compatible. | F11: 1 | G11: pc | H11: 100 | I11: 150 | J11: =F11*H11 | K11: =F11*I11 | M11: Shopee / Lazada / Makerlab PH | N11: 0.96 inch I2C OLED display SSD1306 | O11: Cabinet face display for live readings and IP/WiFi.
A12: To Buy | B12: A7 | C12: Perfboard / Prototype PCB (5×7cm) | D12: Sensors & Probe Electronics | E12: FR-4 double-sided prototype board with plated through-holes, 2.54mm pitch. | F12: 2 | G12: pcs | H12: 25 | I12: 50 | J12: =F12*H12 | K12: =F12*I12 | M12: Shopee / Electronics Store | N12: 5x7cm double sided prototype PCB FR4 | O12: For mounting SHT31 + BH1750 + SCD41 inside probe.
A13: Subtotal — Category A (Sensors & Probe Electronics): | J13: =SUM(J6:J12) | K13: =SUM(K6:K12) | L13: =SUM(L6:L12)
A14: 🏠 CATEGORY B: HANGING SENSOR PROBE HOUSING (PVC BELL REDUCER DESIGN)
A15: To Buy | B15: B1 | C15: 2" to 1" PVC Bell Reducer (White/Gray) | D15: Hanging Sensor Probe Housing | E15: Schedule 40 PVC fitting. 2" bell opening down to 1" neck. Lightweight housing. | F15: 1 | G15: pc | H15: 25 | I15: 45 | J15: =F15*H15 | K15: =F15*I15 | M15: Local Hardware (Citi / Wilcon / Ace) | N15: 2 x 1 PVC bell reducer fitting | O15: Forms inverted bell chamber shielding sensors from mist.
A16: To Buy | B16: B2 | C16: M16 or M20 IP68 Waterproof Cable Gland | D16: Hanging Sensor Probe Housing | E16: Nylon PA66 body, rubber clamping ring, IP68 rated, fits cables 4-8mm / 6-12mm. | F16: 1 | G16: pc | H16: 30 | I16: 60 | J16: =F16*H16 | K16: =F16*I16 | M16: Shopee / Lazada / Hardware | N16: M16 or M20 cable gland IP68 waterproof | O16: Screws into top neck; clamps cable and hangs probe.
A17: To Buy | B17: B3 | C17: PG7 Cable Gland (Nylon, IP68) | D17: Hanging Sensor Probe Housing | E17: Mini cable gland for 3-6.5mm cables, weatherproof sealing. | F17: 2 | G17: pcs | H17: 15 | I17: 25 | J17: =F17*H17 | K17: =F17*I17 | M17: Shopee / Hardware Store | N17: PG7 cable gland nylon IP68 | O17: Internal cable strain relief and wire pass-throughs.
A18: To Buy | B18: B4 | C18: Fine Stainless Steel Mesh / Nylon Filter | D18: Hanging Sensor Probe Housing | E18: 80-120 mesh SS304 wire cloth or dense nylon micron mesh. | F18: 1 | G18: sheet | H18: 30 | I18: 60 | J18: =F18*H18 | K18: =F18*I18 | M18: Hardware Store / Shopee | N18: Stainless steel 304 mesh screen 100 mesh | O18: Glued to 2" bottom rim. Stops droplets, passes CO2.
A19: To Buy | B19: B5 | C19: PTFE Hydrophobic Membrane Disc (13-25mm) | D19: Hanging Sensor Probe Housing | E19: ePTFE breathable membrane, hydrophobic IP67 rating, gas permeable. | F19: 1 | G19: pc | H19: 40 | I19: 80 | J19: =F19*H19 | K19: =F19*I19 | M19: Shopee | N19: PTFE membrane disc sensor waterproof | O19: Glued over SCD41 aperture to prevent condensation.
A20: To Buy | B20: B6 | C20: PVC Solvent Cement & Rapid Epoxy | D20: Hanging Sensor Probe Housing | E20: 100ml PVC cement + 2-part rapid epoxy (Pioneer/Devcon). | F20: 1 | G20: tube | H20: 45 | I20: 80 | J20: =F20*H20 | K20: =F20*I20 | M20: Any Hardware Store | N20: PVC cement Neltex + Pioneer epoxy | O20: Bonds screen to PVC rim and seals gland threads.
A21: To Buy | B21: B7 | C21: Printed Vinyl Label Sticker | D21: Hanging Sensor Probe Housing | E21: Weatherproof vinyl sticker: 'KABUTECH HIYAS — Probe SN-01'. | F21: 1 | G21: pc | H21: 20 | I21: 30 | J21: =F21*H21 | K21: =F21*I21 | M21: Print Shop / DIY Vinyl | N21: Waterproof vinyl sticker printing | O21: Professional thesis branding for probe assembly.
A22: To Buy | B22: B8 | C22: Nylon Cable Zip Ties (100mm) | D22: Hanging Sensor Probe Housing | E22: 2.5mm × 100mm black nylon UV-resistant zip ties (Pack of 100). | F22: 1 | G22: pack | H22: 30 | I22: 45 | J22: =F22*H22 | K22: =F22*I22 | M22: Hardware Store / Shopee | N22: Nylon zip ties 100mm black pack | O22: Internal wire bundling and strain relief.
A23: Subtotal — Category B (Hanging Sensor Probe Housing): | J23: =SUM(J15:J22) | K23: =SUM(K15:K22) | L23: =SUM(L15:L22)
A24: 🧠 CATEGORY C: CONTROLLER BOARD & CORE ELECTRONICS
A25: To Buy | B25: C1 | C25: ESP32-S3 DevKit N16R8 (USB-C) | D25: Controller Board & Core Electronics | E25: 16MB Flash, 8MB PSRAM, 240MHz Dual Core, WiFi 4 + BLE 5.0. Dual USB-C. | F25: 1 | G25: pc | H25: 350 | I25: 500 | J25: =F25*H25 | K25: =F25*I25 | M25: Shopee / Makerlab PH / Circuit Rocks | N25: ESP32-S3 N16R8 DevKit USB-C | O25: Verify 'N16R8' in listing for full memory & speed.
A26: To Buy | B26: C2 | C26: 8-Channel Relay Module (5V, Optocoupled) | D26: Controller Board & Core Electronics | E26: 8-ch optoisolated relay board, active LOW trigger, 10A 250VAC rating. | F26: 1 | G26: pc | H26: 180 | I26: 280 | J26: =F26*H26 | K26: =F26*I26 | M26: Shopee / Lazada / Makerlab PH | N26: 8 channel relay module 5V optocoupler | O26: Controls: Exhaust, Intake, Mister, Light, Solenoid + 3 spares.
A27: To Buy | B27: C3 | C27: Logic Level Shifter (3.3V ↔ 5V, 4-Ch) | D27: Controller Board & Core Electronics | E27: Bi-directional I2C / digital logic level converter with BSS138 MOSFETs. | F27: 1 | G27: pc | H27: 30 | I27: 50 | J27: =F27*H27 | K27: =F27*I27 | M27: Shopee / Lazada | N27: 4 channel logic level converter 3.3V 5V | O27: Protects ESP32 3.3V GPIOs driving 5V relay inputs.
A28: To Buy | B28: C4 | C28: Mini Breadboard / Expansion Strips | D28: Controller Board & Core Electronics | E28: 170-tie point mini solderless breadboard with adhesive backing. | F28: 2 | G28: pcs | H28: 25 | I28: 40 | J28: =F28*H28 | K28: =F28*I28 | M28: Shopee / Electronics Store | N28: 170 tie point mini breadboard | O28: Prototyping power rail distribution inside cabinet.
A29: To Buy | B29: C5 | C29: LM2596 DC-DC Step-Down Buck Converter | D29: Controller Board & Core Electronics | E29: Input 4-40V, Output 1.25-35V adjustable, 3A peak, high efficiency. | F29: 1 | G29: pc | H29: 40 | I29: 70 | J29: =F29*H29 | K29: =F29*I29 | M29: Shopee / Lazada | N29: LM2596 DC-DC buck converter module | O29: Steps down 12V rail to clean 5.0V for MCU & relays.
A30: To Buy | B30: C6 | C30: 5V 1A Voltage Regulator Module (AMS1117) | D30: Controller Board & Core Electronics | E30: Linear regulator module with input/output filter capacitors & power LED. | F30: 1 | G30: pc | H30: 20 | I30: 40 | J30: =F30*H30 | K30: =F30*I30 | M30: Shopee / Electronics Store | N30: AMS1117 5V power supply module | O30: Dedicated filtered 5V rail to prevent relay-induced brownouts.
A31: To Buy | B31: C7 | C31: 3-Position Toggle Switch (Auto/Off/Manual) | D31: Controller Board & Core Electronics | E31: Panel-mount 3-position (ON-OFF-ON) heavy-duty toggle switch. | F31: 1 | G31: pc | H31: 30 | I31: 50 | J31: =F31*H31 | K31: =F31*I31 | M31: Shopee / Hardware Store | N31: Toggle switch 3 position ON-OFF-ON panel mount | O31: Hardware override switch: Auto PID / Off / Manual Mode.
A32: To Buy | B32: C8 | C32: 5mm LEDs (R, G, B, Y) + 220Ω Resistors | D32: Controller Board & Core Electronics | E32: Panel-mount 5mm LEDs with bezels + 1/4W 220Ω current limiting resistors. | F32: 1 | G32: set | H32: 30 | I32: 40 | J32: =F32*H32 | K32: =F32*I32 | M32: Shopee / Electronics Store | N32: 5mm LED with bezel panel mount set | O32: Front panel indicators: Power (G), WiFi (B), Alarm (R), Mode (Y).
A33: To Buy | B33: C9 | C33: Momentary Push Button (12mm, Panel-Mount) | D33: Controller Board & Core Electronics | E33: Waterproof momentary push button, normally open (NO), flush metal head. | F33: 1 | G33: pc | H33: 15 | I33: 30 | J33: =F33*H33 | K33: =F33*I33 | M33: Shopee / Electronics Store | N33: 12mm waterproof momentary push button metal | O33: External Cabinet System Reset / WiFi Provision button.
A34: To Buy | B34: C10 | C34: 10kΩ 1/4W Resistors (Pack of 20) | D34: Controller Board & Core Electronics | E34: 1% tolerance 1/4W metal film through-hole resistors. | F34: 1 | G34: pack | H34: 20 | I34: 30 | J34: =F34*H34 | K34: =F34*I34 | M34: Shopee / Electronics Store | N34: 10k ohm 1/4W metal film resistors pack | O34: I2C pull-ups, button debouncing, switch logic.
A35: To Buy | B35: C11 | C35: 1N4007 Rectifier Diodes (Pack of 10) | D35: Controller Board & Core Electronics | E35: 1000V 1A standard recovery rectifier diode, DO-41 package. | F35: 1 | G35: pack | H35: 15 | I35: 30 | J35: =F35*H35 | K35: =F35*I35 | M35: Shopee / Electronics Store | N35: 1N4007 diode pack 10pcs | O35: Flyback diode protection across pump, solenoid & fan coils.
A36: To Buy | B36: C12 | C36: Inline Blade Fuse Holder (16AWG) + 5A Fuses | D36: Controller Board & Core Electronics | E36: Waterproof automotive inline fuse holder + 5A blade fuses (Pack of 5). | F36: 2 | G36: pcs | H36: 25 | I36: 50 | J36: =F36*H36 | K36: =F36*I36 | M36: Shopee / Automotive Store | N36: Inline blade fuse holder waterproof 16AWG | O36: Protects main 12V rail and high-draw actuator branches.
A37: Subtotal — Category C (Controller Board & Core Electronics): | J37: =SUM(J25:J36) | K37: =SUM(K25:K36) | L37: =SUM(L25:L36)
A38: ⚡ CATEGORY D: POWER SUPPLY & DISTRIBUTION
A39: To Buy | B39: D1 | C39: 12V 5A (60W) Enclosed Switching PSU | D39: Power Supply & Distribution | E39: Metal mesh chassis, universal AC in (110-240V), regulated 12VDC ±1%. | F39: 1 | G39: pc | H39: 600 | I39: 1000 | J39: =F39*H39 | K39: =F39*I39 | M39: Shopee / Lazada / Alexan | N39: 12V 5A switching power supply metal case | O39: Powers entire system safely: ESP32, fans, pump, valve.
A40: To Buy | B40: D2 | C40: IEC C14 Inlet Socket with Fuse & Switch | D40: Power Supply & Distribution | E40: Panel-mount AC socket with built-in 5x20mm fuse drawer & illuminated switch. | F40: 1 | G40: pc | H40: 60 | I40: 100 | J40: =F40*H40 | K40: =F40*I40 | M40: Shopee / Lazada / Alexan | N40: IEC C14 power socket with fuse switch panel mount | O40: Professional computer kettle cord inlet on enclosure face.
...

Sheet 📊 Executive Summary
A1: 🍄 KABUTECH HIYAS — EXECUTIVE BUDGET & PROCUREMENT DASHBOARD
A2: Live Project Financial Overview, Category Allocations & Status Tracking
A4: TOTAL ALLOCATED BUDGET | C4: EST. MIN TOTAL | D4: EST. MAX TOTAL | E4: ACTUAL SPENT | F4: BUDGET REMAINING | G4: TOTAL ITEMS
A5: 15000 | C5: ='📋 Materials Checklist'!J90 | D5: ='📋 Materials Checklist'!K90 | E5: ='📋 Materials Checklist'!L90 | F5: =A5-E5 | G5: 68
A6: Fixed Project Ceiling | C6: Smart Shopee / Lazada | D6: Worst-case retail buffer | E6: Tracked from purchases | F6: Surplus / Buffer | G6: Across 8 Categories
A8: 📊 CATEGORY BUDGET BREAKDOWN & SPENDING SUMMARY
A9: Cat Code | B9: Category Description | C9: Items Count | D9: Est. Min (₱) | E9: Est. Max (₱) | F9: Actual Spent (₱) | G9: % of Budget (Max)
A10: Category A | B10: Sensors & Probe Electronics (Quality-Grade) | C10: 7 | D10: ='📋 Materials Checklist'!J13 | E10: ='📋 Materials Checklist'!K13 | F10: ='📋 Materials Checklist'!L13 | G10: =E10/$A$5
A11: Category B | B11: Hanging Sensor Probe Housing (PVC Bell Reducer Design) | C11: 8 | D11: ='📋 Materials Checklist'!J23 | E11: ='📋 Materials Checklist'!K23 | F11: ='📋 Materials Checklist'!L23 | G11: =E11/$A$5
A12: Category C | B12: Controller Board & Core Electronics | C12: 12 | D12: ='📋 Materials Checklist'!J37 | E12: ='📋 Materials Checklist'!K37 | F12: ='📋 Materials Checklist'!L37 | G12: =E12/$A$5
A13: Category D | B13: Power Supply & Distribution | C13: 7 | D13: ='📋 Materials Checklist'!J46 | E13: ='📋 Materials Checklist'!K46 | F13: ='📋 Materials Checklist'!L46 | G13: =E13/$A$5
A14: Category E | B14: Connectors & Wiring | C14: 10 | D14: ='📋 Materials Checklist'!J58 | E14: ='📋 Materials Checklist'!K58 | F14: ='📋 Materials Checklist'!L58 | G14: =E14/$A$5
A15: Category F | B15: Actuators (The Things Being Controlled) | C15: 12 | D15: ='📋 Materials Checklist'!J72 | E15: ='📋 Materials Checklist'!K72 | F15: ='📋 Materials Checklist'!L72 | G15: =E15/$A$5
A16: Category G | B16: Enclosure & Mounting | C16: 5 | D16: ='📋 Materials Checklist'!J79 | E16: ='📋 Materials Checklist'!K79 | F16: ='📋 Materials Checklist'!L79 | G16: =E16/$A$5
A17: Category H | B17: Miscellaneous, Tools & Fabrication Consumables | C17: 7 | D17: ='📋 Materials Checklist'!J88 | E17: ='📋 Materials Checklist'!K88 | F17: ='📋 Materials Checklist'!L88 | G17: =E17/$A$5
A18: TOTALS | B18: All 8 System Categories Combined | C18: =SUM(C10:C17) | D18: =SUM(D10:D17) | E18: =SUM(E10:E17) | F18: =SUM(F10:F17) | G18: =SUM(G10:G17)
A20: 💡 BUDGET ANALYSIS & KEY TAKEAWAYS:
A21: 1. Best-Case Budget Target: | B21: ₱9,770 — Achievable by taking advantage of Shopee/Lazada monthly sales (e.g., Payday, 10.10, 11.11), platform vouchers, and free shipping coins.
A22: 2. Realistic Budget Target: | B22: ₱12,000–₱13,500 — Leaves a healthy buffer of ₱1,500–₱3,000 within your ₱15,000 cap for unexpected spares, extra wire, or shipping fees.
A23: 3. High-End Worst-Case: | B23: ₱15,550 — Even if buying every single item at peak retail with zero discounts and buying a brand new soldering iron, it sits right at your ₱15k ceiling.
A24: 4. Key Cost Driver: | B24: The SCD41 True NDIR CO₂ Sensor (₱1,800–₱2,500) represents ~18% of total expenditure. It is the single most critical investment for your thesis credibility.

Sheet 🛒 Vendor & Shopping Guide
A1: 🍄 KABUTECH HIYAS — PHILIPPINE SOURCING & PROCUREMENT GUIDE
A2: Recommended Local Vendors, Shopping Batches & Quality Verification Checks
A4: 🏪 RECOMMENDED STORES IN THE PHILIPPINES
A5: Store / Vendor | B5: Platform / Location | C5: Items to Source Here | D5: Pros / Recommendations | E5: Est. Delivery
A6: Makerlab Electronics | B6: Shopee Mall / Lazada / QC Physical | C6: ESP32-S3, Relays, OLED, SHT31, Level Shifter, XKC-Y25 | D6: Fast NCR delivery (1-2 days), tested genuine boards | E6: 1–2 days
A7: CircuitRocks Philippines | B7: Shopee / Website / Mandaluyong | C7: BH1750, SHT31-D, Prototyping PCBs, Connectors | D7: High quality verified sensors, technical support | E7: 1–3 days
A8: e-Gizmo Mechatronix | B8: Taft Ave Manila / Online Store | C8: Sensors, Relays, Breadboards, Headers, Power components | D8: Long-running local supplier, student thesis friendly | E8: 1–3 days
A9: Alexan Commercial | B9: Raon Quiapo / SM Megamall / Online | C9: 12V Switching PSU, IEC C14 Inlets, Switches, Diodes, Fuses | D9: Best for industrial power supplies, enclosure accessories | E9: Same day / 2 days
A10: Shopee Overseas (China) | B10: Shopee App (Search keyword) | C10: SCD41 NDIR CO2 Sensor, GX16 Connectors, Misting Nozzles | D10: 30-50% cheaper on SCD41 and aviation plugs | E10: 5–8 days
A11: Wilcon Depot / Citi Hardware | B11: Local Physical Branches Nationwide | C11: PVC Bell Reducer, Teflon Tape, Hose Clamps, Wall Brackets | D11: Heavy-duty sanitary grade PVC fittings, inspect in-person | E11: Immediate
A12: Ace Hardware / Handyman | B12: Malls Nationwide | C12: Electrical tape, 3M VHB tape, Silicone sealant, Zip ties | D12: Branded adhesives & sealants (3M, Pioneer, Devcon) | E12: Immediate
A14: 📅 RECOMMENDED 4-PHASE ORDERING ROADMAP
A15: Phase | B15: Target Milestone | C15: Items to Order | D15: Purpose & Validation Goal | E15: Est. Spend
A16: Phase 1 | B16: Core Sensors & Logic Bench Test | C16: ESP32-S3, SHT31, BH1750, SCD41, OLED, Jumpers, Breadboard | D16: Bench-test sensor polling, I2C bus scan, and Firebase telemetry transmission. | E16: ₱2,800 – ₱3,600
A17: Phase 2 | B17: Power & Actuator Control Bench Test | C17: 12V PSU, 8-Ch Relay, Logic Shifter, Fans, Misting Pump, Solenoid Valve | D17: Validate relay switching, flyback diodes, and actuator trigger responsiveness. | E17: ₱3,500 – ₱4,800
A18: Phase 3 | B18: Probe & Enclosure Fabrication | C18: IP65 Box, PVC Bell Reducer, Cable Glands, GX16 Plugs, Step Drill Bit, Sealant | D18: Drill enclosure, solder aviation connectors, fabricate waterproof hanging probe. | E18: ₱1,800 – ₱2,600
A19: Phase 4 | B19: Plumbing & Final Deployment | C19: Misting Tubing, Brass Nozzles, Check Valve, Reservoir, Wall Brackets | D19: Assemble plumbing manifold in grow house, calibrate sensors, end-to-end PID test. | E19: ₱1,200 – ₱2,000
A21: 🔍 QUALITY VERIFICATION CHECKLIST (BEFORE YOU BUY)
A22: ESP32-S3 Flash/PSRAM | B22: Ensure listing states 'N16R8' (16MB Flash / 8MB PSRAM). Generic N4 (4MB) has insufficient memory for dual-core FreeRTOS, Firebase queue, and web stack simultaneously.
A23: SCD41 vs SCD30 / MQ-135 | B23: Do NOT accept MQ-135 or CCS811. Only Sensirion SCD40 or SCD41 offers photoacoustic true NDIR CO2 measurement. Look for Sensirion laser-etched metal package.
A24: SHT31 vs DHT11 / DHT22 | B24: DHT11 will fail rapidly at >85% RH in a mushroom house. The Sensirion SHT31-D features an integrated heater and internal humidity polymer rated for 0-100% RH.
A25: Aviation Connectors (GX16) | B25: Order matching Male + Female pairs (GX16-4). 4-pin is standard: Pin 1 = 12V/VCC, Pin 2 = GND, Pin 3 = Signal/SDA, Pin 4 = SCL/Trigger.
A26: Power Supply Quality | B26: Verify the 12V 5A PSU has an aluminum casing with ventilation slots and a trimmer pot to fine-tune 12.0VDC. Avoid unbranded lightweight plastic wall-warts for continuous 24/7 duty.
